<mujoco model="bimanual_X5A_EE">
  <option iterations="50" timestep="0.001" solver="PGS" gravity="0 0 -9.81" />

  <compiler angle="radian" meshdir="meshes" eulerseq="zyx" autolimits="true" />

  <default>
    <joint limited="true" damping="0.01" armature="0.01" frictionloss="0.01" />
    <geom condim="4" contype="1" conaffinity="15" friction="0.9 0.2 0.2" solref="0.001 2" />
    <motor ctrllimited="true" />
    <equality solref="0.001 2" />
    <default class="visualgeom">
      <geom material="visualgeom" condim="1" contype="0" conaffinity="0" />
    </default>
  </default>

  <asset>
    <mesh name="base_link" content_type="model/stl" file="base_link.STL" />
    <mesh name="link1" content_type="model/stl" file="link1.STL" />
    <mesh name="link2" content_type="model/stl" file="link2.STL" />
    <mesh name="link3" content_type="model/stl" file="link3.STL" />
    <mesh name="link4" content_type="model/stl" file="link4.STL" />
    <mesh name="link5" content_type="model/stl" file="link5.STL" />
    <mesh name="link6" content_type="model/stl" file="link6.STL" />
    <mesh name="link7" content_type="model/stl" file="link7.STL" />
    <mesh name="link8" content_type="model/stl" file="link8.STL" />
    <texture name="texplane" type="2d" builtin="checker" rgb1=".0 .0 .0" rgb2=".8 .8 .8" width="100" height="100" />
    <material name="matplane" reflectance="0." texture="texplane" texrepeat="1 1" texuniform="true" />
    <material name="visualgeom" rgba="0.5 0.9 0.2 1" />
  </asset>

  <worldbody>
    <light directional="true" diffuse="0.4 0.4 0.4" specular="0.1 0.1 0.1" pos="0 0 5.0" dir="0 0 -1" castshadow="false" />
    <light directional="true" diffuse="0.6 0.6 0.6" specular="0.2 0.2 0.2" pos="0 0 4" dir="0 0 -1" />
    <geom name="ground" type="plane" pos="0 0 0" size="100 100 0.001" quat="1 0 0 0" material="matplane" condim="3" conaffinity="15" />
    <camera name="fixed" pos="0 -3.0 0.5595892660226525" xyaxes="1 0 0 0 0 1" />
    <camera name="track" mode="trackcom" pos="0 -3.0 0.5595892660226525" xyaxes="1 0 0 0 0 1" />
    <body name="root" pos="0 0 0.05958926602265252" quat="1 0 0 0">
      <site name="imu" size="0.01" pos="0 0 0" />
      <geom pos="0 -0.3 0" quat="1 0 0 0" type="mesh" rgba="0.75294 0.75294 0.75294 1" mesh="base_link" contype="1" conaffinity="0" density="0" group="1" class="visualgeom" />
      <geom type="mesh" rgba="0.75294 0.75294 0.75294 1" mesh="base_link" pos="0 -0.3 0" quat="1 0 0 0" />
      <geom pos="0 0.3 0" quat="1 0 0 0" type="mesh" rgba="0.75294 0.75294 0.75294 1" mesh="base_link" contype="1" conaffinity="0" density="0" group="1" class="visualgeom" />
      <geom type="mesh" rgba="0.75294 0.75294 0.75294 1" mesh="base_link" pos="0 0.3 0" quat="1 0 0 0" />
      <body name="right_link1" pos="0 -0.3 0.0605">
        <inertial pos="0.0054231 -0.0080289 0.017086" quat="0.653281 0.653281 -0.270598 0.270598" mass="0.066982" diaginertia="9e-05 7e-05 3e-05" />
                          <joint name="right_joint1" pos="0 0 0" axis="0 0 1" type="hinge" range="-10 10" actuatorfrcrange="-100 100" />
        <geom type="mesh" rgba="0.79216 0.81961 0.93333 1" mesh="link1" contype="1" conaffinity="0" density="0" group="1" class="visualgeom" />
        <geom type="mesh" rgba="0.79216 0.81961 0.93333 1" mesh="link1" />
        <body name="right_link2" pos="0.02 0 0.04">
          <inertial pos="-0.13237 0.0020852 0.00010549" quat="7.64729e-05 0.706196 -0.000379919 0.708016" mass="1.0795" diaginertia="0.0160501 0.01599 0.000509891" />
                            <joint name="right_joint2" pos="0 0 0" axis="0 1 0" type="hinge" range="-10 10" actuatorfrcrange="-100 100" />
          <geom type="mesh" rgba="0.75294 0.75294 0.75294 1" mesh="link2" contype="1" conaffinity="0" density="0" group="1" class="visualgeom" />
          <geom type="mesh" rgba="0.75294 0.75294 0.75294 1" mesh="link2" />
          <body name="right_link3" pos="-0.264 0 0" quat="-3.67321e-06 1 0 0">
            <inertial pos="0.18531 0.00068376 -0.051638" quat="0.223261 0.638184 0.206685 0.707218" mass="0.54534" diaginertia="0.00424842 0.004221 0.000320578" />
                              <joint name="right_joint3" pos="0 0 0" axis="0 1 0" type="hinge" range="-10 10" actuatorfrcrange="-100 100" />
            <geom type="mesh" rgba="1 0.98431 0.96471 1" mesh="link3" contype="1" conaffinity="0" density="0" group="1" class="visualgeom" />
            <geom type="mesh" rgba="1 0.98431 0.96471 1" mesh="link3" />
            <body name="right_link4" pos="0.245 0 -0.056">
              <inertial pos="0.040231 0.0044807 -0.035335" quat="0.911288 -0.0751532 0.308689 -0.261949" mass="0.11714" diaginertia="0.000275643 0.00021286 7.14977e-05" />
                                <joint name="right_joint4" pos="0 0 0" axis="0 1 0" type="hinge" range="-10 10" actuatorfrcrange="-100 100" />
              <geom type="mesh" rgba="0.79216 0.81961 0.92941 1" mesh="link4" contype="1" conaffinity="0" density="0" group="1" class="visualgeom" />
              <geom type="mesh" rgba="0.79216 0.81961 0.92941 1" mesh="link4" />
              <body name="right_link5" pos="0.06775 0.0005 -0.0865">
                <inertial pos="0.003612 -1.5455e-05 0.055214" quat="0.998188 0 -0.0601752 0" mass="0.63488" diaginertia="0.000838471 0.00082 0.000251529" />
                                  <joint name="right_joint5" pos="0 0 0" axis="0 0 1" type="hinge" range="-10 10" actuatorfrcrange="-100 100" />
                <geom type="mesh" rgba="0.69804 0.69804 0.69804 1" mesh="link5" contype="1" conaffinity="0" density="0" group="1" class="visualgeom" />
                <geom type="mesh" rgba="0.69804 0.69804 0.69804 1" mesh="link5" />
                <body name="right_link6" pos="0.02895 0 0.0865" quat="-3.67321e-06 -1 0 0">
                  <inertial pos="0.041697 2.4368e-05 0.00014464" quat="0.5 0.5 -0.5 0.5" mass="0.44089" diaginertia="0.0005 0.00038 0.00028" />
                  <joint name="right_joint6" pos="0 0 0" axis="1 0 0" type="hinge" range="-10 10" actuatorfrcrange="-100 100" />
                  <geom type="mesh" rgba="0.89804 0.91765 0.92941 1" mesh="link6" contype="1" conaffinity="0" density="0" group="1" class="visualgeom" />
                  <geom type="mesh" rgba="0.89804 0.91765 0.92941 1" mesh="link6" />
                  <body name="right_link7" pos="0.08657 0.024896 -0.0002436">
                    <inertial pos="-0.00035522 -0.007827 -0.0029883" quat="0.5 0.5 0.5 0.5" mass="0.064798" diaginertia="3e-05 3e-05 2e-05" />
                    <joint name="right_joint7" pos="0 0 0" axis="0 1 0" type="slide" range="0 0.044" actuatorfrcrange="-100 100" />
                    <geom type="mesh" rgba="1 1 1 1" mesh="link7" contype="1" conaffinity="0" density="0" group="1" class="visualgeom" />
                    <geom type="mesh" rgba="1 1 1 1" mesh="link7" />
                  </body>
                  <body name="right_link8" pos="0.08657 -0.0249 -0.00024366">
                    <inertial pos="-0.00035522 0.0078277 0.0024201" quat="0.5 0.5 0.5 0.5" mass="0.064798" diaginertia="3e-05 3e-05 2e-05" />
                    <joint name="right_joint8" pos="0 0 0" axis="0 -1 0" type="slide" range="0 0.044" actuatorfrcrange="-100 100" />
                    <geom type="mesh" rgba="1 1 1 1" mesh="link8" contype="1" conaffinity="0" density="0" group="1" class="visualgeom" />
                    <geom type="mesh" rgba="1 1 1 1" mesh="link8" />
                  </body>
                </body>
              </body>
            </body>
          </body>
        </body>
      </body>
      <body name="left_link1" pos="0 0.3 0.0605">
        <inertial pos="0.0054231 -0.0080289 0.017086" quat="0.653281 0.653281 -0.270598 0.270598" mass="0.066982" diaginertia="9e-05 7e-05 3e-05" />
                          <joint name="left_joint1" pos="0 0 0" axis="0 0 1" type="hinge" range="-10 10" actuatorfrcrange="-100 100" />
        <geom type="mesh" rgba="0.79216 0.81961 0.93333 1" mesh="link1" contype="1" conaffinity="0" density="0" group="1" class="visualgeom" />
        <geom type="mesh" rgba="0.79216 0.81961 0.93333 1" mesh="link1" />
        <body name="left_link2" pos="0.02 0 0.04">
          <inertial pos="-0.13237 0.0020852 0.00010549" quat="7.64729e-05 0.706196 -0.000379919 0.708016" mass="1.0795" diaginertia="0.0160501 0.01599 0.000509891" />
                            <joint name="left_joint2" pos="0 0 0" axis="0 1 0" type="hinge" range="-10 10" actuatorfrcrange="-100 100" />
          <geom type="mesh" rgba="0.75294 0.75294 0.75294 1" mesh="link2" contype="1" conaffinity="0" density="0" group="1" class="visualgeom" />
          <geom type="mesh" rgba="0.75294 0.75294 0.75294 1" mesh="link2" />
          <body name="left_link3" pos="-0.264 0 0" quat="-3.67321e-06 1 0 0">
            <inertial pos="0.18531 0.00068376 -0.051638" quat="0.223261 0.638184 0.206685 0.707218" mass="0.54534" diaginertia="0.00424842 0.004221 0.000320578" />
                              <joint name="left_joint3" pos="0 0 0" axis="0 1 0" type="hinge" range="-10 10" actuatorfrcrange="-100 100" />
            <geom type="mesh" rgba="1 0.98431 0.96471 1" mesh="link3" contype="1" conaffinity="0" density="0" group="1" class="visualgeom" />
            <geom type="mesh" rgba="1 0.98431 0.96471 1" mesh="link3" />
            <body name="left_link4" pos="0.245 0 -0.056">
              <inertial pos="0.040231 0.0044807 -0.035335" quat="0.911288 -0.0751532 0.308689 -0.261949" mass="0.11714" diaginertia="0.000275643 0.00021286 7.14977e-05" />
                                <joint name="left_joint4" pos="0 0 0" axis="0 1 0" type="hinge" range="-10 10" actuatorfrcrange="-100 100" />
              <geom type="mesh" rgba="0.79216 0.81961 0.92941 1" mesh="link4" contype="1" conaffinity="0" density="0" group="1" class="visualgeom" />
              <geom type="mesh" rgba="0.79216 0.81961 0.92941 1" mesh="link4" />
              <body name="left_link5" pos="0.06775 0.0005 -0.0865">
                <inertial pos="0.003612 -1.5455e-05 0.055214" quat="0.998188 0 -0.0601752 0" mass="0.63488" diaginertia="0.000838471 0.00082 0.000251529" />
                                  <joint name="left_joint5" pos="0 0 0" axis="0 0 1" type="hinge" range="-10 10" actuatorfrcrange="-100 100" />
                <geom type="mesh" rgba="0.69804 0.69804 0.69804 1" mesh="link5" contype="1" conaffinity="0" density="0" group="1" class="visualgeom" />
                <geom type="mesh" rgba="0.69804 0.69804 0.69804 1" mesh="link5" />
                <body name="left_link6" pos="0.02895 0 0.0865" quat="-3.67321e-06 -1 0 0">
                  <inertial pos="0.041697 2.4368e-05 0.00014464" quat="0.5 0.5 -0.5 0.5" mass="0.44089" diaginertia="0.0005 0.00038 0.00028" />
                  <joint name="left_joint6" pos="0 0 0" axis="1 0 0" type="hinge" range="-10 10" actuatorfrcrange="-100 100" />
                  <geom type="mesh" rgba="0.89804 0.91765 0.92941 1" mesh="link6" contype="1" conaffinity="0" density="0" group="1" class="visualgeom" />
                  <geom type="mesh" rgba="0.89804 0.91765 0.92941 1" mesh="link6" />
                  <body name="left_link7" pos="0.08657 0.024896 -0.0002436">
                    <inertial pos="-0.00035522 -0.007827 -0.0029883" quat="0.5 0.5 0.5 0.5" mass="0.064798" diaginertia="3e-05 3e-05 2e-05" />
                    <joint name="left_joint7" pos="0 0 0" axis="0 1 0" type="slide" range="0 0.044" actuatorfrcrange="-100 100" />
                    <geom type="mesh" rgba="1 1 1 1" mesh="link7" contype="1" conaffinity="0" density="0" group="1" class="visualgeom" />
                    <geom type="mesh" rgba="1 1 1 1" mesh="link7" />
                  </body>
                  <body name="left_link8" pos="0.08657 -0.0249 -0.00024366">
                    <inertial pos="-0.00035522 0.0078277 0.0024201" quat="0.5 0.5 0.5 0.5" mass="0.064798" diaginertia="3e-05 3e-05 2e-05" />
                    <joint name="left_joint8" pos="0 0 0" axis="0 -1 0" type="slide" range="0 0.044" actuatorfrcrange="-100 100" />
                    <geom type="mesh" rgba="1 1 1 1" mesh="link8" contype="1" conaffinity="0" density="0" group="1" class="visualgeom" />
                    <geom type="mesh" rgba="1 1 1 1" mesh="link8" />
                  </body>
                </body>
              </body>
            </body>
          </body>
        </body>
      </body>
    </body>
  </worldbody>

  <actuator>
    <position name="right_joint1" joint="right_joint1" kp="1000" kv="200" ctrlrange="-10 10" />
    <position name="right_joint2" joint="right_joint2" kp="1000" kv="200" ctrlrange="-10 10" />
    <position name="right_joint3" joint="right_joint3" kp="1000" kv="200" ctrlrange="-10 10" />
    <position name="right_joint4" joint="right_joint4" kp="1000" kv="200" ctrlrange="-10 10" />
    <position name="right_joint5" joint="right_joint5" kp="1000" kv="200" ctrlrange="-10 10" />
    <position name="right_joint6" joint="right_joint6" kp="1000" kv="200" ctrlrange="-10 10" />
    <position name="right_joint7" joint="right_joint7" kp="1000" kv="200" ctrlrange="0 0.044" />
    <!-- <position name="right_joint8" joint="right_joint8" kp="1000" ctrlrange="0 0.044" /> -->
    <position name="left_joint1" joint="left_joint1" kp="1000" kv="200" ctrlrange="-10 10" />
    <position name="left_joint2" joint="left_joint2" kp="1000" kv="200" ctrlrange="-10 10" />
    <position name="left_joint3" joint="left_joint3" kp="1000" kv="200" ctrlrange="-10 10" />
    <position name="left_joint4" joint="left_joint4" kp="1000" kv="200" ctrlrange="-10 10" />
    <position name="left_joint5" joint="left_joint5" kp="1000" kv="200" ctrlrange="-10 10" />
    <position name="left_joint6" joint="left_joint6" kp="1000" kv="200" ctrlrange="-10 10" />
    <position name="left_joint7" joint="left_joint7" kp="1000" kv="200" ctrlrange="0 0.044" />
    <!-- <position name="left_joint8" joint="left_joint8" kp="1000" ctrlrange="0 0.044" /> -->
  </actuator>

  <equality>
    <joint name="right_gripper_constraint" joint1="right_joint7" joint2="right_joint8" polycoef="0 -1 0 0 0" />
    <joint name="left_gripper_constraint" joint1="left_joint7" joint2="left_joint8" polycoef="0 -1 0 0 0" />
  </equality>

  <sensor>
    <actuatorpos name="right_joint1_p" actuator="right_joint1" />
    <actuatorvel name="right_joint1_v" actuator="right_joint1" />
    <actuatorfrc name="right_joint1_f" actuator="right_joint1" noise="0.001" />
    <actuatorpos name="right_joint2_p" actuator="right_joint2" />
    <actuatorvel name="right_joint2_v" actuator="right_joint2" />
    <actuatorfrc name="right_joint2_f" actuator="right_joint2" noise="0.001" />
    <actuatorpos name="right_joint3_p" actuator="right_joint3" />
    <actuatorvel name="right_joint3_v" actuator="right_joint3" />
    <actuatorfrc name="right_joint3_f" actuator="right_joint3" noise="0.001" />
    <actuatorpos name="right_joint4_p" actuator="right_joint4" />
    <actuatorvel name="right_joint4_v" actuator="right_joint4" />
    <actuatorfrc name="right_joint4_f" actuator="right_joint4" noise="0.001" />
    <actuatorpos name="right_joint5_p" actuator="right_joint5" />
    <actuatorvel name="right_joint5_v" actuator="right_joint5" />
    <actuatorfrc name="right_joint5_f" actuator="right_joint5" noise="0.001" />
    <actuatorpos name="right_joint6_p" actuator="right_joint6" />
    <actuatorvel name="right_joint6_v" actuator="right_joint6" />
    <actuatorfrc name="right_joint6_f" actuator="right_joint6" noise="0.001" />
    <actuatorpos name="right_joint7_p" actuator="right_joint7" />
    <actuatorvel name="right_joint7_v" actuator="right_joint7" />
    <actuatorfrc name="right_joint7_f" actuator="right_joint7" noise="0.001" />
    <!-- <actuatorpos name="right_joint8_p" actuator="right_joint8" />
    <actuatorvel name="right_joint8_v" actuator="right_joint8" />
    <actuatorfrc name="right_joint8_f" actuator="right_joint8" noise="0.001" /> -->
    <actuatorpos name="left_joint1_p" actuator="left_joint1" /> 
    <actuatorvel name="left_joint1_v" actuator="left_joint1" />
    <actuatorfrc name="left_joint1_f" actuator="left_joint1" noise="0.001" />
    <actuatorpos name="left_joint2_p" actuator="left_joint2" />
    <actuatorvel name="left_joint2_v" actuator="left_joint2" />
    <actuatorfrc name="left_joint2_f" actuator="left_joint2" noise="0.001" />
    <actuatorpos name="left_joint3_p" actuator="left_joint3" />
    <actuatorvel name="left_joint3_v" actuator="left_joint3" />
    <actuatorfrc name="left_joint3_f" actuator="left_joint3" noise="0.001" />
    <actuatorpos name="left_joint4_p" actuator="left_joint4" />
    <actuatorvel name="left_joint4_v" actuator="left_joint4" />
    <actuatorfrc name="left_joint4_f" actuator="left_joint4" noise="0.001" />
    <actuatorpos name="left_joint5_p" actuator="left_joint5" />
    <actuatorvel name="left_joint5_v" actuator="left_joint5" />
    <actuatorfrc name="left_joint5_f" actuator="left_joint5" noise="0.001" />
    <actuatorpos name="left_joint6_p" actuator="left_joint6" />
    <actuatorvel name="left_joint6_v" actuator="left_joint6" />
    <actuatorfrc name="left_joint6_f" actuator="left_joint6" noise="0.001" />
    <actuatorpos name="left_joint7_p" actuator="left_joint7" />
    <actuatorvel name="left_joint7_v" actuator="left_joint7" />
    <actuatorfrc name="left_joint7_f" actuator="left_joint7" noise="0.001" />
    <!-- <actuatorpos name="left_joint8_p" actuator="left_joint8" />
    <actuatorvel name="left_joint8_v" actuator="left_joint8" />
    <actuatorfrc name="left_joint8_f" actuator="left_joint8" noise="0.001" /> -->
    <framequat name="orientation" objtype="site" noise="0.001" objname="imu" />
    <gyro name="angular-velocity" site="imu" noise="0.005" cutoff="34.9" />
  </sensor>
  
  <keyframe>
    <key name="home" qpos="0 0 0 0 0 0 0 0 0 0 0 0 0 0 0 0" ctrl="0 0 0 0 0 0 0 0 0 0 0 0 0 0" />
  </keyframe>
</mujoco>