<?xml version="0.0" ?>
<robot name="bimanual_X5A_EE">
	<link name="root">
		<inertial>
			<origin rpy="0.00000 -0.00000 0.00000" xyz="0.00000 0.00000 0.00000"/>
			<mass value="0.00000"/>
			<inertia ixx="0.00000" ixy="0" ixz="0" iyy="0.00000" iyz="0" izz="0.00000"/>
		</inertial>
	</link>
	<link name="link1_2">
		<inertial>
			<origin rpy="0.00000 -0.00000 0.00000" xyz="0.00000 0.00000 0.00000"/>
			<mass value="0.00000"/>
			<inertia ixx="0.00000" ixy="0" ixz="0" iyy="0.00000" iyz="0" izz="0.00000"/>
		</inertial>
	</link>
	<link name="right_link1">
		<inertial>
			<origin rpy="1.57080 -0.78540 0.00000" xyz="0.00542 -0.00803 0.01709"/>
			<mass value="0.06698"/>
			<inertia ixx="0.00000" ixy="0" ixz="0" iyy="0.00000" iyz="0" izz="0.00000"/>
		</inertial>
	</link>
	<link name="link1_4">
		<inertial>
			<origin rpy="0.00000 -0.00000 0.00000" xyz="0.00000 0.00000 0.00000"/>
			<mass value="0.00000"/>
			<inertia ixx="0.00000" ixy="0" ixz="0" iyy="0.00000" iyz="0" izz="0.00000"/>
		</inertial>
	</link>
	<link name="right_link2">
		<inertial>
			<origin rpy="0.00000 -1.57080 3.14052" xyz="-0.13237 0.00209 0.00011"/>
			<mass value="1.07950"/>
			<inertia ixx="0.00000" ixy="0" ixz="0" iyy="0.00000" iyz="0" izz="0.00000"/>
		</inertial>
	</link>
	<link name="link1_6">
		<inertial>
			<origin rpy="0.00000 -0.00000 0.00000" xyz="0.00000 0.00000 0.00000"/>
			<mass value="0.00000"/>
			<inertia ixx="0.00000" ixy="0" ixz="0" iyy="0.00000" iyz="0" izz="0.00000"/>
		</inertial>
	</link>
	<link name="right_link3">
		<inertial>
			<origin rpy="1.39927 -0.94480 1.71768" xyz="0.18531 0.00068 -0.05164"/>
			<mass value="0.54534"/>
			<inertia ixx="0.00000" ixy="0" ixz="0" iyy="0.00000" iyz="0" izz="0.00000"/>
		</inertial>
	</link>
	<link name="link1_8">
		<inertial>
			<origin rpy="0.00000 -0.00000 0.00000" xyz="0.00000 0.00000 0.00000"/>
			<mass value="0.00000"/>
			<inertia ixx="0.00000" ixy="0" ixz="0" iyy="0.00000" iyz="0" izz="0.00000"/>
		</inertial>
	</link>
	<link name="right_link4">
		<inertial>
			<origin rpy="-0.35811 0.55064 -0.66198" xyz="0.04023 0.00448 -0.03534"/>
			<mass value="0.11714"/>
			<inertia ixx="0.00000" ixy="0" ixz="0" iyy="0.00000" iyz="0" izz="0.00000"/>
		</inertial>
	</link>
	<link name="link1_10">
		<inertial>
			<origin rpy="0.00000 -0.00000 0.00000" xyz="0.00000 0.00000 0.00000"/>
			<mass value="0.00000"/>
			<inertia ixx="0.00000" ixy="0" ixz="0" iyy="0.00000" iyz="0" izz="0.00000"/>
		</inertial>
	</link>
	<link name="right_link5">
		<inertial>
			<origin rpy="0.00000 -0.12042 0.00000" xyz="0.00361 -0.00002 0.05521"/>
			<mass value="0.63488"/>
			<inertia ixx="0.00000" ixy="0" ixz="0" iyy="0.00000" iyz="0" izz="0.00000"/>
		</inertial>
	</link>
	<link name="link1_12">
		<inertial>
			<origin rpy="0.00000 -0.00000 0.00000" xyz="0.00000 0.00000 0.00000"/>
			<mass value="0.00000"/>
			<inertia ixx="0.00000" ixy="0" ixz="0" iyy="0.00000" iyz="0" izz="0.00000"/>
		</inertial>
	</link>
	<link name="right_link6">
		<inertial>
			<origin rpy="0.00000 -1.57080 1.57080" xyz="0.04170 0.00002 0.00014"/>
			<mass value="0.44089"/>
			<inertia ixx="0.00000" ixy="0" ixz="0" iyy="0.00000" iyz="0" izz="0.00000"/>
		</inertial>
	</link>
	<link name="link1_14">
		<inertial>
			<origin rpy="0.00000 -0.00000 0.00000" xyz="0.00000 0.00000 0.00000"/>
			<mass value="0.00000"/>
			<inertia ixx="0.00000" ixy="0" ixz="0" iyy="0.00000" iyz="0" izz="0.00000"/>
		</inertial>
	</link>
	<link name="right_link7">
		<inertial>
			<origin rpy="1.57080 -0.00000 1.57080" xyz="-0.00036 -0.00783 -0.00299"/>
			<mass value="0.06480"/>
			<inertia ixx="0.00000" ixy="0" ixz="0" iyy="0.00000" iyz="0" izz="0.00000"/>
		</inertial>
	</link>
	<link name="link1_16">
		<inertial>
			<origin rpy="0.00000 -0.00000 0.00000" xyz="0.00000 0.00000 0.00000"/>
			<mass value="0.00000"/>
			<inertia ixx="0.00000" ixy="0" ixz="0" iyy="0.00000" iyz="0" izz="0.00000"/>
		</inertial>
	</link>
	<link name="right_link8">
		<inertial>
			<origin rpy="1.57080 -0.00000 1.57080" xyz="-0.00036 0.00783 0.00242"/>
			<mass value="0.06480"/>
			<inertia ixx="0.00000" ixy="0" ixz="0" iyy="0.00000" iyz="0" izz="0.00000"/>
		</inertial>
	</link>
	<link name="link1_18">
		<inertial>
			<origin rpy="0.00000 -0.00000 0.00000" xyz="0.00000 0.00000 0.00000"/>
			<mass value="0.00000"/>
			<inertia ixx="0.00000" ixy="0" ixz="0" iyy="0.00000" iyz="0" izz="0.00000"/>
		</inertial>
	</link>
	<link name="left_link1">
		<inertial>
			<origin rpy="1.57080 -0.78540 0.00000" xyz="0.00542 -0.00803 0.01709"/>
			<mass value="0.06698"/>
			<inertia ixx="0.00000" ixy="0" ixz="0" iyy="0.00000" iyz="0" izz="0.00000"/>
		</inertial>
	</link>
	<link name="link1_20">
		<inertial>
			<origin rpy="0.00000 -0.00000 0.00000" xyz="0.00000 0.00000 0.00000"/>
			<mass value="0.00000"/>
			<inertia ixx="0.00000" ixy="0" ixz="0" iyy="0.00000" iyz="0" izz="0.00000"/>
		</inertial>
	</link>
	<link name="left_link2">
		<inertial>
			<origin rpy="0.00000 -1.57080 3.14052" xyz="-0.13237 0.00209 0.00011"/>
			<mass value="1.07950"/>
			<inertia ixx="0.00000" ixy="0" ixz="0" iyy="0.00000" iyz="0" izz="0.00000"/>
		</inertial>
	</link>
	<link name="link1_22">
		<inertial>
			<origin rpy="0.00000 -0.00000 0.00000" xyz="0.00000 0.00000 0.00000"/>
			<mass value="0.00000"/>
			<inertia ixx="0.00000" ixy="0" ixz="0" iyy="0.00000" iyz="0" izz="0.00000"/>
		</inertial>
	</link>
	<link name="left_link3">
		<inertial>
			<origin rpy="1.39927 -0.94480 1.71768" xyz="0.18531 0.00068 -0.05164"/>
			<mass value="0.54534"/>
			<inertia ixx="0.00000" ixy="0" ixz="0" iyy="0.00000" iyz="0" izz="0.00000"/>
		</inertial>
	</link>
	<link name="link1_24">
		<inertial>
			<origin rpy="0.00000 -0.00000 0.00000" xyz="0.00000 0.00000 0.00000"/>
			<mass value="0.00000"/>
			<inertia ixx="0.00000" ixy="0" ixz="0" iyy="0.00000" iyz="0" izz="0.00000"/>
		</inertial>
	</link>
	<link name="left_link4">
		<inertial>
			<origin rpy="-0.35811 0.55064 -0.66198" xyz="0.04023 0.00448 -0.03534"/>
			<mass value="0.11714"/>
			<inertia ixx="0.00000" ixy="0" ixz="0" iyy="0.00000" iyz="0" izz="0.00000"/>
		</inertial>
	</link>
	<link name="link1_26">
		<inertial>
			<origin rpy="0.00000 -0.00000 0.00000" xyz="0.00000 0.00000 0.00000"/>
			<mass value="0.00000"/>
			<inertia ixx="0.00000" ixy="0" ixz="0" iyy="0.00000" iyz="0" izz="0.00000"/>
		</inertial>
	</link>
	<link name="left_link5">
		<inertial>
			<origin rpy="0.00000 -0.12042 0.00000" xyz="0.00361 -0.00002 0.05521"/>
			<mass value="0.63488"/>
			<inertia ixx="0.00000" ixy="0" ixz="0" iyy="0.00000" iyz="0" izz="0.00000"/>
		</inertial>
	</link>
	<link name="link1_28">
		<inertial>
			<origin rpy="0.00000 -0.00000 0.00000" xyz="0.00000 0.00000 0.00000"/>
			<mass value="0.00000"/>
			<inertia ixx="0.00000" ixy="0" ixz="0" iyy="0.00000" iyz="0" izz="0.00000"/>
		</inertial>
	</link>
	<link name="left_link6">
		<inertial>
			<origin rpy="0.00000 -1.57080 1.57080" xyz="0.04170 0.00002 0.00014"/>
			<mass value="0.44089"/>
			<inertia ixx="0.00000" ixy="0" ixz="0" iyy="0.00000" iyz="0" izz="0.00000"/>
		</inertial>
	</link>
	<link name="link1_30">
		<inertial>
			<origin rpy="0.00000 -0.00000 0.00000" xyz="0.00000 0.00000 0.00000"/>
			<mass value="0.00000"/>
			<inertia ixx="0.00000" ixy="0" ixz="0" iyy="0.00000" iyz="0" izz="0.00000"/>
		</inertial>
	</link>
	<link name="left_link7">
		<inertial>
			<origin rpy="1.57080 -0.00000 1.57080" xyz="-0.00036 -0.00783 -0.00299"/>
			<mass value="0.06480"/>
			<inertia ixx="0.00000" ixy="0" ixz="0" iyy="0.00000" iyz="0" izz="0.00000"/>
		</inertial>
	</link>
	<link name="link1_32">
		<inertial>
			<origin rpy="0.00000 -0.00000 0.00000" xyz="0.00000 0.00000 0.00000"/>
			<mass value="0.00000"/>
			<inertia ixx="0.00000" ixy="0" ixz="0" iyy="0.00000" iyz="0" izz="0.00000"/>
		</inertial>
	</link>
	<link name="left_link8">
		<inertial>
			<origin rpy="1.57080 -0.00000 1.57080" xyz="-0.00036 0.00783 0.00242"/>
			<mass value="0.06480"/>
			<inertia ixx="0.00000" ixy="0" ixz="0" iyy="0.00000" iyz="0" izz="0.00000"/>
		</inertial>
	</link>
	<joint name="right_joint1" type="revolute">
		<parent link="root"/>
		<child link="link1_2"/>
		<limit effort="0.00000" lower="-10.00000" upper="10.00000" velocity="0.00000"/>
		<dynamics damping="1.0" friction="0.0001"/>
		<origin rpy="0.00000 -0.00000 0.00000" xyz="0.00000 -0.30000 0.06050"/>
		<axis xyz="0.00000 0.00000 1.00000"/>
	</joint>
	<joint name="jointfix_7_2" type="fixed">
		<parent link="link1_2"/>
		<child link="right_link1"/>
		<dynamics damping="1.0" friction="0.0001"/>
		<origin rpy="0.00000 -0.00000 0.00000" xyz="0.00000 0.00000 0.00000"/>
		<axis xyz="0.00000 0.00000 0.00000"/>
	</joint>
	<joint name="right_joint2" type="revolute">
		<parent link="right_link1"/>
		<child link="link1_4"/>
		<limit effort="0.00000" lower="-10.00000" upper="10.00000" velocity="0.00000"/>
		<dynamics damping="1.0" friction="0.0001"/>
		<origin rpy="0.00000 -0.00000 0.00000" xyz="0.02000 0.00000 0.04000"/>
		<axis xyz="0.00000 1.00000 0.00000"/>
	</joint>
	<joint name="jointfix_6_4" type="fixed">
		<parent link="link1_4"/>
		<child link="right_link2"/>
		<dynamics damping="1.0" friction="0.0001"/>
		<origin rpy="0.00000 -0.00000 0.00000" xyz="0.00000 0.00000 0.00000"/>
		<axis xyz="0.00000 0.00000 0.00000"/>
	</joint>
	<joint name="right_joint3" type="revolute">
		<parent link="right_link2"/>
		<child link="link1_6"/>
		<limit effort="0.00000" lower="-10.00000" upper="10.00000" velocity="0.00000"/>
		<dynamics damping="1.0" friction="0.0001"/>
		<origin rpy="-3.14159 -0.00000 -0.00000" xyz="-0.26400 0.00000 0.00000"/>
		<axis xyz="0.00000 1.00000 0.00000"/>
	</joint>
	<joint name="jointfix_5_6" type="fixed">
		<parent link="link1_6"/>
		<child link="right_link3"/>
		<dynamics damping="1.0" friction="0.0001"/>
		<origin rpy="0.00000 -0.00000 0.00000" xyz="0.00000 0.00000 0.00000"/>
		<axis xyz="0.00000 0.00000 0.00000"/>
	</joint>
	<joint name="right_joint4" type="revolute">
		<parent link="right_link3"/>
		<child link="link1_8"/>
		<limit effort="0.00000" lower="-10.00000" upper="10.00000" velocity="0.00000"/>
		<dynamics damping="1.0" friction="0.0001"/>
		<origin rpy="0.00000 0.00000 0.00000" xyz="0.24500 0.00000 -0.05600"/>
		<axis xyz="0.00000 1.00000 0.00000"/>
	</joint>
	<joint name="jointfix_4_8" type="fixed">
		<parent link="link1_8"/>
		<child link="right_link4"/>
		<dynamics damping="1.0" friction="0.0001"/>
		<origin rpy="0.00000 -0.00000 0.00000" xyz="0.00000 0.00000 0.00000"/>
		<axis xyz="0.00000 0.00000 0.00000"/>
	</joint>
	<joint name="right_joint5" type="revolute">
		<parent link="right_link4"/>
		<child link="link1_10"/>
		<limit effort="0.00000" lower="-10.00000" upper="10.00000" velocity="0.00000"/>
		<dynamics damping="1.0" friction="0.0001"/>
		<origin rpy="0.00000 -0.00000 0.00000" xyz="0.06775 0.00050 -0.08650"/>
		<axis xyz="0.00000 0.00000 1.00000"/>
	</joint>
	<joint name="jointfix_3_10" type="fixed">
		<parent link="link1_10"/>
		<child link="right_link5"/>
		<dynamics damping="1.0" friction="0.0001"/>
		<origin rpy="0.00000 -0.00000 0.00000" xyz="0.00000 0.00000 0.00000"/>
		<axis xyz="0.00000 0.00000 0.00000"/>
	</joint>
	<joint name="right_joint6" type="revolute">
		<parent link="right_link5"/>
		<child link="link1_12"/>
		<limit effort="0.00000" lower="-10.00000" upper="10.00000" velocity="0.00000"/>
		<dynamics damping="1.0" friction="0.0001"/>
		<origin rpy="3.14159 -0.00000 0.00000" xyz="0.02895 0.00000 0.08650"/>
		<axis xyz="1.00000 0.00000 0.00000"/>
	</joint>
	<joint name="jointfix_2_12" type="fixed">
		<parent link="link1_12"/>
		<child link="right_link6"/>
		<dynamics damping="1.0" friction="0.0001"/>
		<origin rpy="0.00000 -0.00000 0.00000" xyz="0.00000 0.00000 0.00000"/>
		<axis xyz="0.00000 0.00000 0.00000"/>
	</joint>
	<joint name="right_joint7" type="prismatic">
		<parent link="right_link6"/>
		<child link="link1_14"/>
		<limit effort="0.00000" lower="0.00000" upper="0.04400" velocity="0.00000"/>
		<dynamics damping="1.0" friction="0.0001"/>
		<origin rpy="0.00000 -0.00000 0.00000" xyz="0.08657 0.02490 -0.00024"/>
		<axis xyz="0.00000 1.00000 0.00000"/>
	</joint>
	<joint name="jointfix_0_14" type="fixed">
		<parent link="link1_14"/>
		<child link="right_link7"/>
		<dynamics damping="1.0" friction="0.0001"/>
		<origin rpy="0.00000 -0.00000 0.00000" xyz="0.00000 0.00000 0.00000"/>
		<axis xyz="0.00000 0.00000 0.00000"/>
	</joint>
	<joint name="right_joint8" type="prismatic">
		<parent link="right_link6"/>
		<child link="link1_16"/>
		<limit effort="0.00000" lower="0.00000" upper="0.04400" velocity="0.00000"/>
		<dynamics damping="1.0" friction="0.0001"/>
		<origin rpy="0.00000 -0.00000 0.00000" xyz="0.08657 -0.02490 -0.00024"/>
		<axis xyz="0.00000 -1.00000 0.00000"/>
	</joint>
	<joint name="jointfix_1_16" type="fixed">
		<parent link="link1_16"/>
		<child link="right_link8"/>
		<dynamics damping="1.0" friction="0.0001"/>
		<origin rpy="0.00000 -0.00000 0.00000" xyz="0.00000 0.00000 0.00000"/>
		<axis xyz="0.00000 0.00000 0.00000"/>
	</joint>
	<joint name="left_joint1" type="revolute">
		<parent link="root"/>
		<child link="link1_18"/>
		<limit effort="0.00000" lower="-10.00000" upper="10.00000" velocity="0.00000"/>
		<dynamics damping="1.0" friction="0.0001"/>
		<origin rpy="0.00000 -0.00000 0.00000" xyz="0.00000 0.30000 0.06050"/>
		<axis xyz="0.00000 0.00000 1.00000"/>
	</joint>
	<joint name="jointfix_15_18" type="fixed">
		<parent link="link1_18"/>
		<child link="left_link1"/>
		<dynamics damping="1.0" friction="0.0001"/>
		<origin rpy="0.00000 -0.00000 0.00000" xyz="0.00000 0.00000 0.00000"/>
		<axis xyz="0.00000 0.00000 0.00000"/>
	</joint>
	<joint name="left_joint2" type="revolute">
		<parent link="left_link1"/>
		<child link="link1_20"/>
		<limit effort="0.00000" lower="-10.00000" upper="10.00000" velocity="0.00000"/>
		<dynamics damping="1.0" friction="0.0001"/>
		<origin rpy="0.00000 -0.00000 0.00000" xyz="0.02000 0.00000 0.04000"/>
		<axis xyz="0.00000 1.00000 0.00000"/>
	</joint>
	<joint name="jointfix_14_20" type="fixed">
		<parent link="link1_20"/>
		<child link="left_link2"/>
		<dynamics damping="1.0" friction="0.0001"/>
		<origin rpy="0.00000 -0.00000 0.00000" xyz="0.00000 0.00000 0.00000"/>
		<axis xyz="0.00000 0.00000 0.00000"/>
	</joint>
	<joint name="left_joint3" type="revolute">
		<parent link="left_link2"/>
		<child link="link1_22"/>
		<limit effort="0.00000" lower="-10.00000" upper="10.00000" velocity="0.00000"/>
		<dynamics damping="1.0" friction="0.0001"/>
		<origin rpy="-3.14159 -0.00000 -0.00000" xyz="-0.26400 0.00000 0.00000"/>
		<axis xyz="0.00000 1.00000 0.00000"/>
	</joint>
	<joint name="jointfix_13_22" type="fixed">
		<parent link="link1_22"/>
		<child link="left_link3"/>
		<dynamics damping="1.0" friction="0.0001"/>
		<origin rpy="0.00000 -0.00000 0.00000" xyz="0.00000 0.00000 0.00000"/>
		<axis xyz="0.00000 0.00000 0.00000"/>
	</joint>
	<joint name="left_joint4" type="revolute">
		<parent link="left_link3"/>
		<child link="link1_24"/>
		<limit effort="0.00000" lower="-10.00000" upper="10.00000" velocity="0.00000"/>
		<dynamics damping="1.0" friction="0.0001"/>
		<origin rpy="0.00000 0.00000 0.00000" xyz="0.24500 0.00000 -0.05600"/>
		<axis xyz="0.00000 1.00000 0.00000"/>
	</joint>
	<joint name="jointfix_12_24" type="fixed">
		<parent link="link1_24"/>
		<child link="left_link4"/>
		<dynamics damping="1.0" friction="0.0001"/>
		<origin rpy="0.00000 -0.00000 0.00000" xyz="0.00000 0.00000 0.00000"/>
		<axis xyz="0.00000 0.00000 0.00000"/>
	</joint>
	<joint name="left_joint5" type="revolute">
		<parent link="left_link4"/>
		<child link="link1_26"/>
		<limit effort="0.00000" lower="-10.00000" upper="10.00000" velocity="0.00000"/>
		<dynamics damping="1.0" friction="0.0001"/>
		<origin rpy="0.00000 -0.00000 0.00000" xyz="0.06775 0.00050 -0.08650"/>
		<axis xyz="0.00000 0.00000 1.00000"/>
	</joint>
	<joint name="jointfix_11_26" type="fixed">
		<parent link="link1_26"/>
		<child link="left_link5"/>
		<dynamics damping="1.0" friction="0.0001"/>
		<origin rpy="0.00000 -0.00000 0.00000" xyz="0.00000 0.00000 0.00000"/>
		<axis xyz="0.00000 0.00000 0.00000"/>
	</joint>
	<joint name="left_joint6" type="revolute">
		<parent link="left_link5"/>
		<child link="link1_28"/>
		<limit effort="0.00000" lower="-10.00000" upper="10.00000" velocity="0.00000"/>
		<dynamics damping="1.0" friction="0.0001"/>
		<origin rpy="3.14159 -0.00000 0.00000" xyz="0.02895 0.00000 0.08650"/>
		<axis xyz="1.00000 0.00000 0.00000"/>
	</joint>
	<joint name="jointfix_10_28" type="fixed">
		<parent link="link1_28"/>
		<child link="left_link6"/>
		<dynamics damping="1.0" friction="0.0001"/>
		<origin rpy="0.00000 -0.00000 0.00000" xyz="0.00000 0.00000 0.00000"/>
		<axis xyz="0.00000 0.00000 0.00000"/>
	</joint>
	<joint name="left_joint7" type="prismatic">
		<parent link="left_link6"/>
		<child link="link1_30"/>
		<limit effort="0.00000" lower="0.00000" upper="0.04400" velocity="0.00000"/>
		<dynamics damping="1.0" friction="0.0001"/>
		<origin rpy="0.00000 -0.00000 0.00000" xyz="0.08657 0.02490 -0.00024"/>
		<axis xyz="0.00000 1.00000 0.00000"/>
	</joint>
	<joint name="jointfix_8_30" type="fixed">
		<parent link="link1_30"/>
		<child link="left_link7"/>
		<dynamics damping="1.0" friction="0.0001"/>
		<origin rpy="0.00000 -0.00000 0.00000" xyz="0.00000 0.00000 0.00000"/>
		<axis xyz="0.00000 0.00000 0.00000"/>
	</joint>
	<joint name="left_joint8" type="prismatic">
		<parent link="left_link6"/>
		<child link="link1_32"/>
		<limit effort="0.00000" lower="0.00000" upper="0.04400" velocity="0.00000"/>
		<dynamics damping="1.0" friction="0.0001"/>
		<origin rpy="0.00000 -0.00000 0.00000" xyz="0.08657 -0.02490 -0.00024"/>
		<axis xyz="0.00000 -1.00000 0.00000"/>
	</joint>
	<joint name="jointfix_9_32" type="fixed">
		<parent link="link1_32"/>
		<child link="left_link8"/>
		<dynamics damping="1.0" friction="0.0001"/>
		<origin rpy="0.00000 -0.00000 0.00000" xyz="0.00000 0.00000 0.00000"/>
		<axis xyz="0.00000 0.00000 0.00000"/>
	</joint>
</robot>
